<?xml version="1.0" ?>
<!-- This URDF was automatically created by SolidWorks to URDF Exporter! Originally created by Stephen Brawner (brawner@gmail.com) 
     Commit Version: 1.6.0-4-g7f85cfe  Build Version: 1.6.7995.38578
     For more information, please see http://wiki.ros.org/sw_urdf_exporter -->
<robot
  name="painter" xmlns:xacro="http://ros.org/wiki/xacro">
    <link name="world"/>
      <joint name="base_link_joint" type="fixed">
          <origin xyz="0 0 0" rpy="0 0 0"/>
          <parent link="world"/>
          <child link="base_link"/>
      </joint>
  
  <link
    name="base_link">
    <inertial>
      <origin
        xyz="6.99094974730696E-06 -0.000159353517555083 0.0184354407542913"
        rpy="0 0 0" />
      <mass
        value="0.706324323688928" />
      <inertia
        ixx="0.00115557612091012"
        ixy="4.80089164310127E-08"
        ixz="7.87550619112089E-08"
        iyy="0.00114584541323477"
        iyz="1.99545213436522E-07"
        izz="0.00212897019994227" />
    </inertial>
    <visual>
      <origin
        xyz="0 0 0"
        rpy="0 0 0" />
      <geometry>
        <mesh
          filename="package://painter/meshes/base_link.STL" />
      </geometry>
      <material
        name="">
        <color
          rgba="0.792156862745098 0.819607843137255 0.933333333333333 1" />
      </material>
    </visual>
    <collision>
      <origin
        xyz="0 0 0"
        rpy="0 0 0" />
      <geometry>
        <mesh
          filename="package://painter/meshes/base_link.STL" />
      </geometry>
    </collision>
  </link>
  <link
    name="link1">
    <inertial>
      <origin
        xyz="4.71782343587634E-06 0.0120536613840594 0.078476312508854"
        rpy="0 0 0" />
      <mass
        value="3.0735503792484" />
      <inertia
        ixx="0.0114771435058708"
        ixy="-2.0666647740559E-07"
        ixz="-9.91049366335361E-07"
        iyy="0.0107166358536185"
        iyz="-0.000858549804742859"
        izz="0.0101197474684978" />
    </inertial>
    <visual>
      <origin
        xyz="0 0 0"
        rpy="0 0 0" />
      <geometry>
        <mesh
          filename="package://painter/meshes/link1.STL" />
      </geometry>
      <material
        name="">
        <color
          rgba="0.792156862745098 0.819607843137255 0.933333333333333 1" />
      </material>
    </visual>
    <collision>
      <origin
        xyz="0 0 0"
        rpy="0 0 0" />
      <geometry>
        <mesh
          filename="package://painter/meshes/link1.STL" />
      </geometry>
    </collision>
  </link>
  <joint
    name="joint1"
    type="revolute">
    <origin
      xyz="0 -0.000438474601031136 0.038"
      rpy="0 0 0" />
    <parent
      link="base_link" />
    <child
      link="link1" />
    <axis
      xyz="0 0 1" />
    <limit
      lower="-100"
      upper="100"
      effort="0"
      velocity="0" />
  </joint>
  <link
    name="link2">
    <inertial>
      <origin
        xyz="-8.33375719819229E-06 -0.251045155323553 0.0843367597288987"
        rpy="0 0 0" />
      <mass
        value="8.71240999185708" />
      <inertia
        ixx="0.0965259605259693"
        ixy="-5.63570815114311E-09"
        ixz="3.6828407589725E-06"
        iyy="0.0199170992677181"
        iyz="0.000589153400061216"
        izz="0.0949166239140944" />
    </inertial>
    <visual>
      <origin
        xyz="0 0 0"
        rpy="0 0 0" />
      <geometry>
        <mesh
          filename="package://painter/meshes/link2.STL" />
      </geometry>
      <material
        name="">
        <color
          rgba="0.792156862745098 0.819607843137255 0.933333333333333 1" />
      </material>
    </visual>
    <collision>
      <origin
        xyz="0 0 0"
        rpy="0 0 0" />
      <geometry>
        <mesh
          filename="package://painter/meshes/link2.STL" />
      </geometry>
    </collision>
  </link>
  <joint
    name="joint2"
    type="revolute">
    <origin
      xyz="0 0.0864384746010307 0.0899999999999895"
      rpy="-1.5707963267949 0 0" />
    <parent
      link="link1" />
    <child
      link="link2" />
    <axis
      xyz="0 0 1" />
    <limit
      lower="-100"
      upper="100"
      effort="0"
      velocity="0" />
  </joint>
  <link
    name="link3">
    <inertial>
      <origin
        xyz="0.25692166044976 -0.00114919485395999 0.0564693903291458"
        rpy="0 0 0" />
      <mass
        value="4.65343533330622" />
      <inertia
        ixx="0.00595615938549713"
        ixy="0.000204077816166074"
        ixz="-0.000130408925284081"
        iyy="0.0517117716162758"
        iyz="1.56787116301245E-07"
        izz="0.0514235407807962" />
    </inertial>
    <visual>
      <origin
        xyz="0 0 0"
        rpy="0 0 0" />
      <geometry>
        <mesh
          filename="package://painter/meshes/link3.STL" />
      </geometry>
      <material
        name="">
        <color
          rgba="0.792156862745098 0.819607843137255 0.933333333333333 1" />
      </material>
    </visual>
    <collision>
      <origin
        xyz="0 0 0"
        rpy="0 0 0" />
      <geometry>
        <mesh
          filename="package://painter/meshes/link3.STL" />
      </geometry>
    </collision>
  </link>
  <joint
    name="joint3"
    type="revolute">
    <origin
      xyz="0 -0.6129 0.0218907105399895"
      rpy="-3.14159265358979 0 -1.5707963267949" />
    <parent
      link="link2" />
    <child
      link="link3" />
    <axis
      xyz="0 0 1" />
    <limit
      lower="-100"
      upper="100"
      effort="0"
      velocity="0" />
  </joint>
  <link
    name="link4">
    <inertial>
      <origin
        xyz="0.00973734864134168 2.6739214219057E-06 0.0463972272902905"
        rpy="0 0 0" />
      <mass
        value="0.728503865444533" />
      <inertia
        ixx="0.0008837567961745"
        ixy="7.57834287599428E-08"
        ixz="-9.07970531936917E-05"
        iyy="0.00111504671598659"
        iyz="3.05733229078505E-08"
        izz="0.00103094377986364" />
    </inertial>
    <visual>
      <origin
        xyz="0 0 0"
        rpy="0 0 0" />
      <geometry>
        <mesh
          filename="package://painter/meshes/link4.STL" />
      </geometry>
      <material
        name="">
        <color
          rgba="0.792156862745098 0.819607843137255 0.933333333333333 1" />
      </material>
    </visual>
    <collision>
      <origin
        xyz="0 0 0"
        rpy="0 0 0" />
      <geometry>
        <mesh
          filename="package://painter/meshes/link4.STL" />
      </geometry>
    </collision>
  </link>
  <joint
    name="joint4"
    type="revolute">
    <origin
      xyz="0.571594265007505 -0.00256050981835861 -0.00199999999999886"
      rpy="-3.14159265358979 0 0" />
    <parent
      link="link3" />
    <child
      link="link4" />
    <axis
      xyz="0 0 1" />
    <limit
      lower="-100"
      upper="100"
      effort="0"
      velocity="0" />
  </joint>
  <link
    name="link5">
    <inertial>
      <origin
        xyz="-3.52511220609586E-06 0.0097375194176495 0.0463971697278001"
        rpy="0 0 0" />
      <mass
        value="0.728508237534515" />
      <inertia
        ixx="0.00111505088577656"
        ixy="-7.87591461924635E-08"
        ixz="-2.89928643008247E-08"
        iyy="0.000883745500230314"
        iyz="-9.07966735661595E-05"
        izz="0.00103092125220075" />
    </inertial>
    <visual>
      <origin
        xyz="0 0 0"
        rpy="0 0 0" />
      <geometry>
        <mesh
          filename="package://painter/meshes/link5.STL" />
      </geometry>
      <material
        name="">
        <color
          rgba="0.792156862745098 0.819607843137255 0.933333333333333 1" />
      </material>
    </visual>
    <collision>
      <origin
        xyz="0 0 0"
        rpy="0 0 0" />
      <geometry>
        <mesh
          filename="package://painter/meshes/link5.STL" />
      </geometry>
    </collision>
  </link>
  <joint
    name="joint5"
    type="revolute">
    <origin
      xyz="0.0617000000000003 0 0.0539999999999999"
      rpy="1.5707963267949 0 1.57079632679076" />
    <parent
      link="link4" />
    <child
      link="link5" />
    <axis
      xyz="0 0 1" />
    <limit
      lower="-100"
      upper="100"
      effort="0"
      velocity="0" />
  </joint>
  <link
    name="link6">
    <inertial>
      <origin
        xyz="0.000569051703420323 -0.000116680573712502 0.0478255754108547"
        rpy="0 0 0" />
      <mass
        value="0.260353111618422" />
      <inertia
        ixx="0.000354567373833919"
        ixy="-1.15024514307977E-06"
        ixz="-4.63038502289799E-07"
        iyy="0.00034919176737072"
        iyz="9.46612029825172E-08"
        izz="0.000194595464124705" />
    </inertial>
    <visual>
      <origin
        xyz="0 0 0"
        rpy="0 0 0" />
      <geometry>
        <mesh
          filename="package://painter/meshes/link6.STL" />
      </geometry>
      <material
        name="">
        <color
          rgba="0.792156862745098 0.819607843137255 0.933333333333333 1" />
      </material>
    </visual>
    <collision>
      <origin
        xyz="0 0 0"
        rpy="0 0 0" />
      <geometry>
        <mesh
          filename="package://painter/meshes/link6.STL" />
      </geometry>
    </collision>
  </link>
  <joint
    name="joint6"
    type="revolute">
    <origin
      xyz="0 0.0617000000000418 0.0539999496926415"
      rpy="-1.5707963267949 0 0" />
    <parent
      link="link5" />
    <child
      link="link6" />
    <axis
      xyz="0 0 1" />
    <limit
      lower="-100"
      upper="100"
      effort="0"
      velocity="0" />
  </joint>

  <!-- ##### Joint Controlllers #####-->

    <ros2_control name="GazeboSystem" type="system">
    <hardware>
      <plugin>gazebo_ros2_control/GazeboSystem</plugin>
      </hardware>

      <!-- Joint 1 position controller-->
      <joint name="joint1">
        <command_interface name="position">
          <param name="min">-6.2832</param>
          <param name="max">6.2832</param>
        </command_interface>
        <state_interface name="position"/>
        <state_interface name="velocity"/>
      </joint>

      <!-- Joint 1 velocity controller-->
      <joint name="joint1">
        <command_interface name="velocity">
          <param name="min">-1000</param>
          <param name="max">1000</param>
        </command_interface>
        <state_interface name="position"/>
        <state_interface name="velocity"/>
      </joint>

      <!-- Joint 2 controller-->
      <joint name="joint2">
        <command_interface name="position">
          <param name="min">-6.2832</param>
          <param name="max">6.2832</param>
        </command_interface>
        <state_interface name="position"/>
        <state_interface name="velocity"/>
      </joint>

      <!-- Joint 2 velocity controller-->
      <joint name="joint2">
        <command_interface name="velocity">
          <param name="min">-1000</param>
          <param name="max">1000</param>
        </command_interface>
        <state_interface name="position"/>
        <state_interface name="velocity"/>
      </joint>

      <!-- Joint 3 position controller-->
      <joint name="joint3">
        <command_interface name="position">
          <param name="min">-2.7925</param>
          <param name="max">2.7925</param>
        </command_interface>
        <state_interface name="position"/>
        <state_interface name="velocity"/>
      </joint>

      <!-- Joint 3 velocity controller-->
      <joint name="joint3">
        <command_interface name="velocity">
          <param name="min">-1000</param>
          <param name="max">1000</param>
        </command_interface>
        <state_interface name="position"/>
        <state_interface name="velocity"/>
      </joint>

      <!-- Joint 4 position controller-->
      <joint name="joint4">
        <command_interface name="position">
          <param name="min">-6.2832</param>
          <param name="max">6.2832</param>
        </command_interface>
        <state_interface name="position"/>
        <state_interface name="velocity"/>
      </joint>

      <!-- Joint 4 velocity controller-->
      <joint name="joint4">
        <command_interface name="velocity">
          <param name="min">-1000</param>
          <param name="max">1000</param>
        </command_interface>
        <state_interface name="position"/>
        <state_interface name="velocity"/>
      </joint>

      <!-- Joint 5 position controller-->
      <joint name="joint5">
        <command_interface name="position">
          <param name="min">-6.2832</param>
          <param name="max">6.2832</param>
        </command_interface>
        <state_interface name="position"/>
        <state_interface name="velocity"/>
      </joint>

      <!-- Joint 5 velocity controller-->
      <joint name="joint1">
        <command_interface name="velocity">
          <param name="min">-1000</param>
          <param name="max">1000</param>
        </command_interface>
        <state_interface name="position"/>
        <state_interface name="velocity"/>
      </joint>

      <!-- Joint 6 position controller-->
      <joint name="joint6">
        <command_interface name="position">
          <param name="min">-6.2832</param>
          <param name="max">6.2832</param>
        </command_interface>
        <state_interface name="position"/>
        <state_interface name="velocity"/>
      </joint>

      <!-- Joint 6 velocity controller-->
      <joint name="joint6">
        <command_interface name="velocity">
          <param name="min">-1000</param>
          <param name="max">1000</param>
        </command_interface>
        <state_interface name="position"/>
        <state_interface name="velocity"/>
      </joint>

    </ros2_control>

  <gazebo>
    <plugin name="gazebo_ros2_control" filename="libgazebo_ros2_control.so">
      <robot_sim_type>gazebo_ros2_control/GazeboSystem</robot_sim_type>
      <parameters>$(find painter)/config/control.yaml</parameters>
      </plugin>
  </gazebo>

  <!-- ########## -->

</robot>